<?xml version="1.0" ?>
<robot name="hbot" xmlns:xacro="http://ros.org/wiki/xacro">
  <xacro:include filename="$(find hbot_description)/urdf/inertials.xacro" />
  <xacro:include filename="$(find hbot_description)/urdf/materials.xacro" />
  <!-- Define some constants -->
  <xacro:property name="base_width" value="0.14"/>
  <xacro:property name="base_height" value="0.08"/>
  <xacro:property name="base_length" value="0.17"/>
  <xacro:property name="base_mass" value="1.0"/>

  <xacro:property name="wheel_radius" value="0.0325"/>
  <xacro:property name="wheel_width" value="0.025"/>
  <xacro:property name="wheel_ygap" value="0.035"/>
  <xacro:property name="wheel_zoff" value="0.05"/>
  <xacro:property name="wheel_xoff" value="0.05"/>

  <xacro:property name="caster_radius" value="0.01"/>
  <xacro:property name="caster_xoff" value="0.07"/>

  <link name="base_footprint"/>
  <joint name="base_footprint_to_base_link" type="fixed">
    <parent link="base_footprint"/>
    <child link="base_link"/>
    <origin xyz="0 0 0" rpy="0 0 0"/>
  </joint>

  <link name="base_link">
    <visual>
      <geometry>
        <box size="${base_length} ${base_width} ${base_height}"/>
      </geometry>
      <material name="Cyan">
        <color rgba="0 1 1 0.5"/>
      </material>
    </visual>
    <collision>
      <geometry>
        <box size="${base_length} ${base_width} ${base_height}"/>
      </geometry>
    </collision>
    <xacro:solid_cuboid_inertial
      rpy="0 0 0"
      xyz="0 0 0"
      mass="${base_mass}"
      x="${base_length}"
      y="${base_width}"
      z="${base_height}"
    />
  </link>

  <!-- Wheel -->
  <xacro:macro name="wheel" params="prefix x_reflect y_reflect">
    <link name="${prefix}_link">
      <visual>
        <origin xyz="0 0 0" rpy="${pi/2} 0 0"/>
        <geometry>
          <cylinder radius="${wheel_radius}" length="${wheel_width}"/>
          <cylinder radius="0.005" length="0.01">
            <origin xyz="0 0 ${wheel_width/2+0.005}" rpy="0 0 0"/>
          </cylinder>
        </geometry>
        <material name="black"/>
      </visual>
      <collision>
        <origin xyz="0 0 0" rpy="${pi/2} 0 0"/>
        <geometry>
          <cylinder radius="${wheel_radius}" length="${wheel_width}"/>
        </geometry>
      </collision>
      <xacro:solid_cylinder_inertial
        rpy="0 0 0"
        xyz="0 0 0"
        mass="0.1"
        radius="${wheel_radius}"
        length="${wheel_width}"
      />
    </link>

    <joint name="${prefix}_joint" type="continuous">
      <parent link="base_link"/>
      <child link="${prefix}_link"/>
      <origin xyz="${x_reflect*wheel_xoff} ${y_reflect*(base_width/2+wheel_ygap)} ${-wheel_zoff}" rpy="0 0 0"/>
      <axis xyz="0 1 0"/>
    </joint>
  </xacro:macro>

  <xacro:wheel prefix="left_wheel" x_reflect="-1" y_reflect="1"/>
  <xacro:wheel prefix="right_wheel" x_reflect="-1" y_reflect="-1"/>

  <!-- Caster -->
  <link name="front_caster">
    <visual>
      <geometry>
        <!-- <sphere radius="${(wheel_radius+wheel_zoff-(base_height/2))}"/> -->
        <sphere radius="${caster_radius}"/>
      </geometry>
      <material name="black"/>
    </visual>
    <collision>
      <geometry>
        <sphere radius="${caster_radius}"/>
      </geometry>
    </collision>
    <xacro:solid_cuboid_inertial
      rpy="0 0 0"
      xyz="0 0 0"
      mass="0.1"
      x="${caster_radius}"
      y="${caster_radius}"
      z="${caster_radius}"
    />
  </link>

  <joint name="front_caster_joint" type="fixed">
    <parent link="base_link"/>
    <child link="front_caster"/>
    <origin xyz="${caster_xoff} 0.0 ${-wheel_zoff-caster_radius}" rpy="0 0 0"/>
  </joint>

  <!-- Lidar -->
  <link name="lidar_link">
    <visual>
      <geometry>
        <cylinder radius="0.03" length="0.025"/>
      </geometry>
      <material name="yellow"/>
    </visual>
    <collision>
      <geometry>
        <cylinder radius="0.03" length="0.025"/>
      </geometry>
    </collision>
    <xacro:solid_cylinder_inertial
      rpy="0 0 0"
      xyz="0 0 0"
      mass="0.1"
      radius="0.03"
      length="0.025"
    />
  </link>

  <joint name="lidar_joint" type="fixed">
    <parent link="base_link"/>
    <child link="lidar_link"/>
    <origin xyz="0 0 ${base_height/2+0.015}" rpy="0 0 0"/>
  </joint>

  <gazebo reference="lidar_link">
    <sensor name="lidar" type="ray">
      <always_on>true</always_on>
      <visualize>false</visualize>
      <update_rate>15</update_rate>
      <ray>
        <scan>
          <horizontal>
            <samples>360</samples>
            <resolution>1</resolution>
            <min_angle>-${pi}</min_angle>
            <max_angle>${pi}</max_angle>
          </horizontal>
        </scan>
        <range>
          <min>0.25</min>
          <max>6.0</max>
          <resolution>0.02</resolution>
        </range>
        <noise>
          <type>gaussian</type>
          <mean>0.0</mean>
          <stddev>0.01</stddev>
        </noise>
      </ray>
      <plugin name="scan" filename="libgazebo_ros_ray_sensor.so">
        <ros>
          <remapping>~/out:=scan</remapping>
        </ros>
        <output_type>sensor_msgs/LaserScan</output_type>
        <frame_name>lidar_link</frame_name>
      </plugin>
    </sensor>
  </gazebo>
  <gazebo reference="lidar_link">
    <material>Gazebo/Yellow</material>
  </gazebo>

  <gazebo>
    <plugin name="two_front_wheeled_diff_drive" filename="libgazebo_ros_diff_drive.so">

      <update_rate>30</update_rate>

      <left_joint>left_wheel_joint</left_joint>
      <right_joint>right_wheel_joint</right_joint>

      <wheel_separation>${base_width + 2 * wheel_ygap}</wheel_separation>
      <wheel_diameter>${wheel_radius * 2.0}</wheel_diameter>

      <max_wheel_torque>20</max_wheel_torque>
      <max_wheel_acceleration>1.0</max_wheel_acceleration>

      <command_topic>cmd_vel</command_topic>

      <publish_odom>true</publish_odom>

      <publish_odom_tf>true</publish_odom_tf>

      <publish_wheel_tf>true</publish_wheel_tf>

      <odometry_topic>odom</odometry_topic>
      <odometry_frame>odom</odometry_frame>
      <robot_base_frame>base_footprint</robot_base_frame>

      <odometry_source>1</odometry_source>
      <ros>
        <remapping>odom:=wheel/odometry</remapping>
      </ros>
    </plugin>
  </gazebo>

</robot>
